## 如何使用rxjs重新发起一个请求

> RxJS 中提供的 catchError 操作符帮助我们处理请求错误时重新发起新请求，这个是Promise做不到的。

### catchError 如何工作
与其他操作符一样，catchError 只是一个函数，接受一个 Observable，输出一个 Observable。每次调用catchError时需要传入一个错误处理函数。

catchError 操作符将一个可能出错的 Observable 作为输入，并发出和输入一样的 Observable，如果没有错误，catchError 产生的输出 Observable 与输入 Observable 完全相同。


### catchError 基本使用示例
```ts

    const http$ = this.http.get<Course[]>('/api/courses');

    http$
        .pipe(
            catchError(err => of([]))
        )
        .subscribe(
            res => console.log('HTTP response', res),
            err => console.log('HTTP Error', err),
            () => console.log('HTTP request completed.')
        ); 
```


### 结合 delayWhen 实现延时重试